<?xml version="1.0" ?>
<robot name="cma_urdf"
  xmlns:xacro="http://www.ros.org/wiki/xacro">

  <xacro:include filename="$(find cma_urdf_description)/urdf/materials.xacro" />
  <xacro:include filename="$(find cma_urdf_description)/urdf/cma_urdf.trans" />
  <xacro:include filename="$(find cma_urdf_description)/urdf/cma_urdf.gazebo" />
  <xacro:include filename="$(find realsense2_description)/urdf/_d435.urdf.xacro"/>
  <xacro:include filename="$(find robotiq_85_description)/urdf/robotiq_85_gripper.xacro"/>

  <link name="world" />

  <link name="base_link">
    <visual>
      <origin rpy="0 0 0" xyz="0 0 0"/>
      <geometry>
        <mesh filename="package://cma_urdf_description/meshes/table2.dae" scale="0.01 0.01 0.01"/>
      </geometry>
      <material name="silver"/>
    </visual>
    <collision>
      <origin rpy="0 0 0" xyz="0 0 0"/>
      <geometry>
        <mesh filename="package://cma_urdf_description/meshes/table.stl" scale="0.001 0.001 0.001"/>
      </geometry>
    </collision>
  </link>

  <link name="robot_to_table_adp_1">
    <inertial>
      <origin rpy="0 0 0" xyz="-0.10160000000000019 -0.10160000000000002 0.01056181707210805"/>
      <mass value="8.798853472720092"/>
      <inertia ixx="0.03741" ixy="0.0" ixz="0.0" iyy="0.03741" iyz="-0.0" izz="0.07371"/>
    </inertial>
    <visual>
      <origin rpy="0 0 0" xyz="-0.5842 -0.3556 -0.016"/>
      <geometry>
        <mesh filename="package://cma_urdf_description/meshes/robot_to_table_adp_1.stl" scale="0.001 0.001 0.001"/>
      </geometry>
      <material name="silver"/>
    </visual>
    <collision>
      <origin rpy="0 0 0" xyz="-0.5842 -0.3556 -0.016"/>
      <geometry>
        <mesh filename="package://cma_urdf_description/meshes/robot_to_table_adp_1.stl" scale="0.001 0.001 0.001"/>
      </geometry>
    </collision>
  </link>

  <link name="Base_UR5_1">
    <inertial>
      <origin rpy="0 0 0" xyz="1.4232860621410381e-05 0.038282955879581804 0.05630526686916636"/>
      <mass value="6.017293428658217"/>
      <inertia ixx="0.090513" ixy="2e-06" ixz="4e-06" iyy="0.011877" iyz="0.01078" izz="0.09152"/>
    </inertial>
    <visual>
      <origin rpy="0 0 0" xyz="-0.4826 -0.254 -0.046"/>
      <geometry>
        <mesh filename="package://cma_urdf_description/meshes/Base_UR5_1.stl" scale="0.001 0.001 0.001"/>
      </geometry>
      <material name="silver"/>
    </visual>
    <collision>
      <origin rpy="0 0 0" xyz="-0.4826 -0.254 -0.046"/>
      <geometry>
        <mesh filename="package://cma_urdf_description/meshes/Base_UR5_1.stl" scale="0.001 0.001 0.001"/>
      </geometry>
    </collision>
  </link>

  <link name="Link1_UR5_1">
    <inertial>
      <origin rpy="0 0 0" xyz="-6.849514455620209e-09 -0.010909793967197823 0.06351880218055075"/>
      <mass value="12.621938032794217"/>
      <inertia ixx="0.030809" ixy="0.0" ixz="-0.0" iyy="0.027066" iyz="0.000743" izz="0.02624"/>
    </inertial>
    <visual>
      <origin rpy="0 0 0" xyz="-0.4826 -0.254 -0.1451"/>
      <geometry>
        <mesh filename="package://cma_urdf_description/meshes/Link1_UR5_1.stl" scale="0.001 0.001 0.001"/>
      </geometry>
      <material name="silver"/>
    </visual>
    <collision>
      <origin rpy="0 0 0" xyz="-0.4826 -0.254 -0.1451"/>
      <geometry>
        <mesh filename="package://cma_urdf_description/meshes/Link1_UR5_1.stl" scale="0.001 0.001 0.001"/>
      </geometry>
    </collision>
  </link>

  <link name="Link2_UR5_1">
    <inertial>
      <origin rpy="0 0 0" xyz="4.605402337265474e-09 -0.06350976997942634 0.21250002923894115"/>
      <mass value="27.334504083061912"/>
      <inertia ixx="1.110326" ixy="0.0" ixz="0.0" iyy="1.10119" iyz="0.0" izz="0.05819"/>
    </inertial>
    <visual>
      <origin rpy="0 0 0" xyz="-0.4826 -0.1796 -0.2085"/>
      <geometry>
        <mesh filename="package://cma_urdf_description/meshes/Link2_UR5_1.stl" scale="0.001 0.001 0.001"/>
      </geometry>
      <material name="silver"/>
    </visual>
    <collision>
      <origin rpy="0 0 0" xyz="-0.4826 -0.1796 -0.2085"/>
      <geometry>
        <mesh filename="package://cma_urdf_description/meshes/Link2_UR5_1.stl" scale="0.001 0.001 0.001"/>
      </geometry>
    </collision>
  </link>

  <link name="Link3_UR5_1">
    <inertial>
      <origin rpy="0 0 0" xyz="-2.9563169799406985e-06 0.057186964790381045 0.14791854418095085"/>
      <mass value="14.0014424889426"/>
      <inertia ixx="0.421335" ixy="1e-06" ixz="1.1e-05" iyy="0.417307" iyz="-0.027579" izz="0.02107"/>
    </inertial>
    <visual>
      <origin rpy="0 0 0" xyz="-0.4826 -0.1796 -0.6335"/>
      <geometry>
        <mesh filename="package://cma_urdf_description/meshes/Link3_UR5_1.stl" scale="0.001 0.001 0.001"/>
      </geometry>
      <material name="silver"/>
    </visual>
    <collision>
      <origin rpy="0 0 0" xyz="-0.4826 -0.1796 -0.6335"/>
      <geometry>
        <mesh filename="package://cma_urdf_description/meshes/Link3_UR5_1.stl" scale="0.001 0.001 0.001"/>
      </geometry>
    </collision>
  </link>

  <link name="Link4_UR5_1">
    <inertial>
      <origin rpy="0 0 0" xyz="7.862227992705417e-06 -0.062093450006130035 -0.002547992766358753"/>
      <mass value="5.167091211713838"/>
      <inertia ixx="0.008583" ixy="2e-06" ixz="1e-06" iyy="0.005396" iyz="-0.0002" izz="0.006947"/>
    </inertial>
    <visual>
      <origin rpy="0 0 0" xyz="-0.4826 -0.2011 -1.02575"/>
      <geometry>
        <mesh filename="package://cma_urdf_description/meshes/Link4_UR5_1.stl" scale="0.001 0.001 0.001"/>
      </geometry>
      <material name="silver"/>
    </visual>
    <collision>
      <origin rpy="0 0 0" xyz="-0.4826 -0.2011 -1.02575"/>
      <geometry>
        <mesh filename="package://cma_urdf_description/meshes/Link4_UR5_1.stl" scale="0.001 0.001 0.001"/>
      </geometry>
    </collision>
  </link>

  <link name="Link5_UR5_1">
    <inertial>
      <origin rpy="0 0 0" xyz="-9.684678712595929e-06 0.0031103043138043934 0.04584822329807814"/>
      <mass value="4.229065191905357"/>
      <inertia ixx="0.005491" ixy="1e-06" ixz="2e-06" iyy="0.003861" iyz="-5.8e-05" izz="0.00473"/>
    </inertial>
    <visual>
      <origin rpy="0 0 0" xyz="-0.4826 -0.1207 -1.07205"/>
      <geometry>
        <mesh filename="package://cma_urdf_description/meshes/Link5_UR5_1.stl" scale="0.001 0.001 0.001"/>
      </geometry>
      <material name="silver"/>
    </visual>
    <collision>
      <origin rpy="0 0 0" xyz="-0.4826 -0.1207 -1.07205"/>
      <geometry>
        <mesh filename="package://cma_urdf_description/meshes/Link5_UR5_1.stl" scale="0.001 0.001 0.001"/>
      </geometry>
    </collision>
  </link>

  <link name="Link6_UR5_1">
    <inertial>
      <origin rpy="0 0 0" xyz="4.89386309254769e-12 -0.0250238691012189 -1.7988520705225497e-05"/>
      <mass value="1.7186317710700016"/>
      <inertia ixx="0.000958" ixy="0.0" ixz="-0.0" iyy="0.001192" iyz="1e-06" izz="0.000964"/>
    </inertial>
    <visual>
      <origin rpy="0 0 0" xyz="-0.4826 -0.0744 -1.12545"/>
      <geometry>
        <mesh filename="package://cma_urdf_description/meshes/Link6_UR5_1_and_VG10.stl" scale="0.001 0.001 0.001"/>
      </geometry>
      <material name="silver"/>
    </visual>
    <collision>
      <origin rpy="0 0 0" xyz="-0.4826 -0.0744 -1.12545"/>
      <geometry>
        <mesh filename="package://cma_urdf_description/meshes/Link6_UR5_1_and_VG10.stl" scale="0.001 0.001 0.001"/>
      </geometry>
    </collision>
  </link>
  
      <joint name="${prefix}ee_fixed_joint" type="fixed">
      <parent link="${prefix}Link6_UR5_1" />
      <child link = "${prefix}ee_link" />
      <origin xyz="0.0 ${wrist_3_length} 0.0" rpy="0.0 0.0 ${pi/2.0}" />
    </joint>

    <link name="${prefix}ee_link">
      <collision>
        <geometry>
          <box size="0.01 0.01 0.01"/>
        </geometry>
        <surface>
          <friction>
            <ode>
              <mu>10</mu>
              <mu2>10</mu2>
            </ode>
          </friction>
        </surface>
        <origin rpy="0 0 0" xyz="-0.01 0 0"/>
      </collision>
    </link>

    <link name="vacuum_gripper">
      <gravity>0</gravity>
      <visual>
        <origin rpy="0 0 0" xyz="0 0 0"/>
        <geometry>
          <cylinder radius="0.005" length="0.01"/>
        </geometry>
        <material name="transparent">
          <color rgba="0 0 0 0"/>
        </material>
      </visual>
      <inertial>
        <origin rpy="0 0 0" xyz="0.000000 0.000000 0.000000"/>
        <mass value="0.0001"/>
        <inertia ixx="1e-08" ixy="0" ixz="0" iyy="1e-08" iyz="0" izz="1e-08"/>
      </inertial>
    </link>

    <joint name="gripper_joint" type="revolute">
      <axis xyz="1 0 0" />
      <parent link="ee_link" />
      <child link="vacuum_gripper" />
      <origin rpy="0 1.5708 0" xyz="0.01 0.0125 0" />
      <limit effort="50" velocity="50" lower="0" upper="0" />
      <dynamics damping="0.0" friction="10"/>
    </joint>

  <gazebo>
      <plugin name="gazebo_ros_vacuum_gripper" filename="libgazebo_ros_vacuum_gripper.so">
        <robotNamespace>/ur5/vacuum_gripper</robotNamespace>
        <bodyName>vacuum_gripper</bodyName>
        <topicName>grasping</topicName>
	<maxForce>50</maxForce>
        <maxDistance>0.05</maxDistance>
        <minDistance>0.01</minDistance>
      </plugin>
  </gazebo>


    <link name="vacuum_gripper1">
      <gravity>0</gravity>
      <visual>
        <origin rpy="0 0 0" xyz="0 0 0"/>
        <geometry>
          <cylinder radius="0.005" length="0.01"/>
        </geometry>
        <material name="transparent">
          <color rgba="0 0 0 0"/>
        </material>
      </visual>
      <inertial>
        <origin rpy="0 0 0" xyz="0.000000 0.000000 0.000000"/>
        <mass value="0.0001"/>
        <inertia ixx="1e-08" ixy="0" ixz="0" iyy="1e-08" iyz="0" izz="1e-08"/>
      </inertial>
    </link>

    <joint name="gripper_joint1" type="revolute">
      <axis xyz="1 0 0" />
      <parent link="ee_link" />
      <child link="vacuum_gripper1" />
      <origin rpy="0 1.5708 0" xyz="0.01 -0.0125 0" />
      <limit effort="50" velocity="50" lower="0" upper="0" />
      <dynamics damping="0.0" friction="10"/>
    </joint>

  <gazebo>
      <plugin name="gazebo_ros_vacuum_gripper1" filename="libgazebo_ros_vacuum_gripper.so">
        <robotNamespace>/ur5/vacuum_gripper1</robotNamespace>
        <bodyName>vacuum_gripper1</bodyName>
        <topicName>grasping1</topicName>
	<maxForce>50</maxForce>
        <maxDistance>0.05</maxDistance>
        <minDistance>0.01</minDistance>
      </plugin>
  </gazebo>


    <link name="vacuum_gripper2">
      <gravity>0</gravity>
      <visual>
        <origin rpy="0 0 0" xyz="0 0 0"/>
        <geometry>
          <cylinder radius="0.005" length="0.01"/>
        </geometry>
        <material name="transparent">
          <color rgba="0 0 0 0"/>
        </material>
      </visual>
      <inertial>
        <origin rpy="0 0 0" xyz="0.000000 0.000000 0.000000"/>
        <mass value="0.0001"/>
        <inertia ixx="1e-08" ixy="0" ixz="0" iyy="1e-08" iyz="0" izz="1e-08"/>
      </inertial>
    </link>

    <joint name="gripper_joint2" type="revolute">
      <axis xyz="1 0 0" />
      <parent link="ee_link" />
      <child link="vacuum_gripper2" />
      <origin rpy="0 1.5708 0" xyz="0.01 0 0.0125" />
      <limit effort="50" velocity="50" lower="0" upper="0" />
      <dynamics damping="0.0" friction="10"/>
    </joint>

  <gazebo>
      <plugin name="gazebo_ros_vacuum_gripper2" filename="libgazebo_ros_vacuum_gripper.so">
        <robotNamespace>/ur5/vacuum_gripper2</robotNamespace>
        <bodyName>vacuum_gripper2</bodyName>
        <topicName>grasping2</topicName>
	<maxForce>50</maxForce>
        <maxDistance>0.05</maxDistance>
        <minDistance>0.01</minDistance>
      </plugin>
  </gazebo>


    <link name="vacuum_gripper3">
      <gravity>0</gravity>
      <visual>
        <origin rpy="0 0 0" xyz="0 0 0"/>
        <geometry>
          <cylinder radius="0.005" length="0.01"/>
        </geometry>
        <material name="transparent">
          <color rgba="0 0 0 0"/>
        </material>
      </visual>
      <inertial>
        <origin rpy="0 0 0" xyz="0.000000 0.000000 0.000000"/>
        <mass value="0.0001"/>
        <inertia ixx="1e-08" ixy="0" ixz="0" iyy="1e-08" iyz="0" izz="1e-08"/>
      </inertial>
    </link>

    <joint name="gripper_joint3" type="revolute">
      <axis xyz="1 0 0" />
      <parent link="ee_link" />
      <child link="vacuum_gripper3" />
      <origin rpy="0 1.5708 0" xyz="0.01 0 -0.0125" />
      <limit effort="50" velocity="50" lower="0" upper="0" />
      <dynamics damping="0.0" friction="10"/>
    </joint>

  <gazebo>
      <plugin name="gazebo_ros_vacuum_gripper3" filename="libgazebo_ros_vacuum_gripper.so">
        <robotNamespace>/ur5/vacuum_gripper3</robotNamespace>
        <bodyName>vacuum_gripper3</bodyName>
        <topicName>grasping2</topicName>
	<maxForce>50</maxForce>
        <maxDistance>0.05</maxDistance>
        <minDistance>0.01</minDistance>
      </plugin>
  </gazebo>

  <link name="vacuum_gripper4">
    <gravity>0</gravity>
    <visual>
      <origin rpy="0 0 0" xyz="0 0 0"/>
      <geometry>
        <cylinder radius="0.005" length="0.01"/>
      </geometry>
      <material name="transparent">
        <color rgba="0 0 0 0"/>
      </material>
    </visual>
    <inertial>
      <origin rpy="0 0 0" xyz="0.000000 0.000000 0.000000"/>
      <mass value="0.0001"/>
      <inertia ixx="1e-08" ixy="0" ixz="0" iyy="1e-08" iyz="0" izz="1e-08"/>
    </inertial>
  </link>

  <joint name="gripper_joint4" type="revolute">
    <axis xyz="1 0 0" />
    <parent link="ee_link" />
    <child link="vacuum_gripper4" />
    <origin rpy="0 1.5708 0" xyz="0.01 0 0" />
    <limit effort="50" velocity="50" lower="0" upper="0" />
    <dynamics damping="0.0" friction="10"/>
  </joint>

  <gazebo>
    <plugin name="gazebo_ros_vacuum_gripper4" filename="libgazebo_ros_vacuum_gripper.so">
      <robotNamespace>/ur5/vacuum_gripper4</robotNamespace>
      <bodyName>vacuum_gripper4</bodyName>
      <topicName>grasping4</topicName>
  <maxForce>50</maxForce>
      <maxDistance>0.05</maxDistance>
      <minDistance>0.01</minDistance>
    </plugin>
  </gazebo>

  <link name="vacuum_gripper5">
    <gravity>0</gravity>
    <visual>
      <origin rpy="0 0 0" xyz="0 0 0"/>
      <geometry>
        <cylinder radius="0.005" length="0.01"/>
      </geometry>
      <material name="transparent">
        <color rgba="0 0 0 0"/>
      </material>
    </visual>
    <inertial>
      <origin rpy="0 0 0" xyz="0.000000 0.000000 0.000000"/>
      <mass value="0.0001"/>
      <inertia ixx="1e-08" ixy="0" ixz="0" iyy="1e-08" iyz="0" izz="1e-08"/>
    </inertial>
  </link>

  <joint name="gripper_joint5" type="revolute">
    <axis xyz="1 0 0" />
    <parent link="ee_link" />
    <child link="vacuum_gripper5" />
    <origin rpy="0 1.5708 0" xyz="0.01 0.0125 0.0125" />
    <limit effort="50" velocity="50" lower="0" upper="0" />
    <dynamics damping="0.0" friction="10"/>
  </joint>

<gazebo>
    <plugin name="gazebo_ros_vacuum_gripper" filename="libgazebo_ros_vacuum_gripper.so">
      <robotNamespace>/ur5/vacuum_gripper5</robotNamespace>
      <bodyName>vacuum_gripper5</bodyName>
      <topicName>grasping5</topicName>
<maxForce>50</maxForce>
      <maxDistance>0.05</maxDistance>
      <minDistance>0.01</minDistance>
    </plugin>
</gazebo>


  <link name="vacuum_gripper6">
    <gravity>0</gravity>
    <visual>
      <origin rpy="0 0 0" xyz="0 0 0"/>
      <geometry>
        <cylinder radius="0.005" length="0.01"/>
      </geometry>
      <material name="transparent">
        <color rgba="0 0 0 0"/>
      </material>
    </visual>
    <inertial>
      <origin rpy="0 0 0" xyz="0.000000 0.000000 0.000000"/>
      <mass value="0.0001"/>
      <inertia ixx="1e-08" ixy="0" ixz="0" iyy="1e-08" iyz="0" izz="1e-08"/>
    </inertial>
  </link>

  <joint name="gripper_joint6" type="revolute">
    <axis xyz="1 0 0" />
    <parent link="ee_link" />
    <child link="vacuum_gripper6" />
    <origin rpy="0 1.5708 0" xyz="0.01 -0.0125 0.0125" />
    <limit effort="50" velocity="50" lower="0" upper="0" />
    <dynamics damping="0.0" friction="10"/>
  </joint>

<gazebo>
    <plugin name="gazebo_ros_vacuum_gripper1" filename="libgazebo_ros_vacuum_gripper.so">
      <robotNamespace>/ur5/vacuum_gripper6</robotNamespace>
      <bodyName>vacuum_gripper6</bodyName>
      <topicName>grasping6</topicName>
<maxForce>50</maxForce>
      <maxDistance>0.05</maxDistance>
      <minDistance>0.01</minDistance>
    </plugin>
</gazebo>


  <link name="vacuum_gripper7">
    <gravity>0</gravity>
    <visual>
      <origin rpy="0 0 0" xyz="0 0 0"/>
      <geometry>
        <cylinder radius="0.005" length="0.01"/>
      </geometry>
      <material name="transparent">
        <color rgba="0 0 0 0"/>
      </material>
    </visual>
    <inertial>
      <origin rpy="0 0 0" xyz="0.000000 0.000000 0.000000"/>
      <mass value="0.0001"/>
      <inertia ixx="1e-08" ixy="0" ixz="0" iyy="1e-08" iyz="0" izz="1e-08"/>
    </inertial>
  </link>

  <joint name="gripper_joint7" type="revolute">
    <axis xyz="1 0 0" />
    <parent link="ee_link" />
    <child link="vacuum_gripper7" />
    <origin rpy="0 1.5708 0" xyz="0.01 0.0125 -0.0125" />
    <limit effort="50" velocity="50" lower="0" upper="0" />
    <dynamics damping="0.0" friction="10"/>
  </joint>

<gazebo>
    <plugin name="gazebo_ros_vacuum_gripper7" filename="libgazebo_ros_vacuum_gripper.so">
      <robotNamespace>/ur5/vacuum_gripper7</robotNamespace>
      <bodyName>vacuum_gripper7</bodyName>
      <topicName>grasping7</topicName>
<maxForce>50</maxForce>
      <maxDistance>0.05</maxDistance>
      <minDistance>0.01</minDistance>
    </plugin>
</gazebo>


  <link name="vacuum_gripper8">
    <gravity>0</gravity>
    <visual>
      <origin rpy="0 0 0" xyz="0 0 0"/>
      <geometry>
        <cylinder radius="0.005" length="0.01"/>
      </geometry>
      <material name="transparent">
        <color rgba="0 0 0 0"/>
      </material>
    </visual>
    <inertial>
      <origin rpy="0 0 0" xyz="0.000000 0.000000 0.000000"/>
      <mass value="0.0001"/>
      <inertia ixx="1e-08" ixy="0" ixz="0" iyy="1e-08" iyz="0" izz="1e-08"/>
    </inertial>
  </link>

  <joint name="gripper_joint8" type="revolute">
    <axis xyz="1 0 0" />
    <parent link="ee_link" />
    <child link="vacuum_gripper8" />
    <origin rpy="0 1.5708 0" xyz="0.01 -0.0125 -0.0125" />
    <limit effort="50" velocity="50" lower="0" upper="0" />
    <dynamics damping="0.0" friction="10"/>
  </joint>

<gazebo>
    <plugin name="gazebo_ros_vacuum_gripper8" filename="libgazebo_ros_vacuum_gripper.so">
      <robotNamespace>/ur5/vacuum_gripper8</robotNamespace>
      <bodyName>vacuum_gripper8</bodyName>
      <topicName>grasping8</topicName>
<maxForce>50</maxForce>
      <maxDistance>0.05</maxDistance>
      <minDistance>0.01</minDistance>
    </plugin>
</gazebo>

  <link name="camera_mount_1">
    <inertial>
      <origin rpy="0 0 0" xyz="5.835308347634793e-10 0.005987651723056972 0.03546806600852759"/>
      <mass value="0.47184000408712967"/>
      <inertia ixx="0.000606" ixy="0.0" ixz="-0.0" iyy="0.000964" iyz="0.0" izz="0.000369"/>
    </inertial>
    <visual>
      <origin rpy="0 0 0" xyz="-0.4826 -0.04665 -1.12545"/>
      <geometry>
        <mesh filename="package://cma_urdf_description/meshes/camera_mount_1.stl" scale="0.001 0.001 0.001"/>
      </geometry>
      <material name="silver"/>
    </visual>
    <collision>
      <origin rpy="0 0 0" xyz="-0.4826 -0.04665 -1.12545"/>
      <geometry>
        <mesh filename="package://cma_urdf_description/meshes/camera_mount_1.stl" scale="0.001 0.001 0.001"/>
      </geometry>
    </collision>
  </link>

  <link name="WRIST_CAMERA_20171116_v2_1">
    <inertial>
      <origin rpy="0 0 0" xyz="0.017204159491027715 -0.005175220524266128 -0.02290143817742174"/>
      <mass value="0.547658826768176"/>
      <inertia ixx="0.000308" ixy="-0.0" ixz="1e-06" iyy="0.000499" iyz="1e-05" izz="0.000221"/>
    </inertial>
    <visual>
      <origin rpy="0 0 0" xyz="-0.464922 -0.0211 -1.143128"/>
      <geometry>
        <mesh filename="package://cma_urdf_description/meshes/WRIST_CAMERA_20171116_v2_1.stl" scale="0.001 0.001 0.001"/>
      </geometry>
      <material name="silver"/>
    </visual>
    <collision>
      <origin rpy="0 0 0" xyz="-0.464922 -0.0211 -1.143128"/>
      <geometry>
        <mesh filename="package://cma_urdf_description/meshes/WRIST_CAMERA_20171116_v2_1.stl" scale="0.001 0.001 0.001"/>
      </geometry>
    </collision>
  </link>

  <joint name="base_to_world_link" type="fixed">
    <parent link="world"/>
    <child link="base_link"/>
  </joint>

  <joint name="Rigid10" type="fixed">
    <origin rpy="0 0 0" xyz="0.5842 0.3556 0.016"/>
    <parent link="base_link"/>
    <child link="robot_to_table_adp_1"/>
  </joint>

  <joint name="Rigid11" type="fixed">
    <origin rpy="0 0 0" xyz="-0.1016 -0.1016 0.03"/>
    <parent link="robot_to_table_adp_1"/>
    <child link="Base_UR5_1"/>
  </joint>

  <joint name="rev_a1" type="revolute">
    <origin rpy="0 0 0" xyz="0.0 0.0 0.0991"/>
    <parent link="Base_UR5_1"/>
    <child link="Link1_UR5_1"/>
    <axis xyz="-0.0 0.0 -1.0"/>
    <limit lower="0" upper="6.28318530718" velocity="5" effort="1000"/>
  </joint>

  <joint name="rev_a2" type="revolute">
    <origin rpy="0 0 0" xyz="0.0 -0.0744 0.0634"/>
    <parent link="Link1_UR5_1"/>
    <child link="Link2_UR5_1"/>
    <axis xyz="-0.0 1.0 0.0"/>
    <limit lower="-1.57079632679" upper="3.1415" velocity="5" effort="1000"/>
  </joint>

  <joint name="rev_a3" type="revolute">
    <origin rpy="0 0 0" xyz="0.0 0.0 0.425"/>
    <parent link="Link2_UR5_1"/>
    <child link="Link3_UR5_1"/>
    <axis xyz="0.0 1.0 -0.0"/>
    <limit lower="0.0" upper="3.1415" velocity="5" effort="1000"/>
  </joint>

  <joint name="rev_a4" type="revolute">
    <origin rpy="0 0 0" xyz="0.0 0.0215 0.39225"/>
    <parent link="Link3_UR5_1"/>
    <child link="Link4_UR5_1"/>
    <axis xyz="-0.0 -1.0 -0.0"/>
    <limit lower="-3.1415" upper="3.1415" velocity="5" effort="1000"/>
  </joint>

  <joint name="rev_a5" type="revolute">
    <origin rpy="0 0 0" xyz="0.0 -0.0804 0.0463"/>
    <parent link="Link4_UR5_1"/>
    <child link="Link5_UR5_1"/>
    <axis xyz="-0.0 -0.0 1.0"/>
    <limit lower="0" upper="3.1415" velocity="5" effort="1000"/>
  </joint>

  <joint name="rev_a6" type="revolute">
    <origin rpy="0 0 0" xyz="0.0 -0.0463 0.0534"/>
    <parent link="Link5_UR5_1"/>
    <child link="Link6_UR5_1"/>
    <axis xyz="0.0 -1.0 -0.0"/>
    <limit lower="-3.1415" upper="3.1415" velocity="5" effort="1000"/>
  </joint>

  <joint name="Rigid42" type="fixed">
    <origin rpy="0 0 0" xyz="0.0 -0.02775 0.0"/>
    <parent link="Link6_UR5_1"/>
    <child link="camera_mount_1"/>
  </joint>

  <joint name="Rigid43" type="fixed">
    <origin rpy="0 0 0" xyz="-0.017678 -0.0533 0.017678"/>
    <parent link="Link6_UR5_1"/>
    <child link="WRIST_CAMERA_20171116_v2_1"/>
  </joint>

  <xacro:sensor_d435 name="realsense_d435" topics_ns="camera" parent="Link6_UR5_1" publish_pointcloud="true">
    <origin xyz="0 -0.0379 0.0495" rpy="0 0 -1.57079632679" />

  </xacro:sensor_d435>

  <xacro:robotiq_85_gripper parent="Link6_UR5_1" prefix="">
    <origin xyz="0 -0.0668 0" rpy="0 0 -1.57079632679" />
  </xacro:robotiq_85_gripper>

</robot>
